Workbook

Sheet 2025
A1: Contas dos xuxus
A2: *Atualizado até 31/07
A3: Conta | B3: 45681 | C3: 45712 | D3: 45740 | E3: 45771 | F3: 45801 | G3: 45832 | H3: 45862 | I3: 45893 | J3: 45924 | K3: 45954 | L3: 45985 | M3: 46015 | O3: Média Gastos 2025
A4: IPTU | C4: 910.16 | D4: 910.16 | E4: 910.16 | F4: 910.16 | G4: 910.16 | H4: 910.16 | I4: 910.16 | J4: 910.16 | K4: 910.16 | L4: 910.16 | M4: 0 | O4: =IFERROR(AVERAGE(B4:M4),0) -> 827.41818
A5: Condomínio | B5: 150 | C5: 150 | D5: 150 | E5: 150 | F5: 150 | G5: 150 | H5: 150 | I5: 150 | J5: 150 | K5: 150 | L5: 150 | M5: 150 | O5: =IFERROR(AVERAGE(B5:M5),0) -> 150
A6: Água | B6: 115.07 | C6: 377.76 | D6: ='Cartão de Crédito'!F5-E6 -> 944.8 | E6: ='Cartão de Crédito'!G5 -> 0 | F6: ='Cartão de Crédito'!H5 -> 0 | G6: =528.31+588.53 -> 1116.84 | H6: ='Cartão de Crédito'!J5 -> 258.84 | I6: ='Cartão de Crédito'!K5 -> 278.83 | J6: ='Cartão de Crédito'!L5 -> 319.53 | K6: ='Cartão de Crédito'!M5 -> 0 | L6: ='Cartão de Crédito'!N5 -> 174.93 | M6: ='Cartão de Crédito'!O5 -> 131.29 | O6: =IFERROR(AVERAGE(B6:M6),0) -> 309.82417
A7: Gás | B7: 206.74 | C7: 389.05 | D7: 373.24 | E7: 265.41 | F7: 367 | G7: 587.56 | H7: 528.42 | I7: 446.69 | J7: 220.81 | K7: 116.46 | L7: 325.48 | M7: 79.55 | O7: =IFERROR(AVERAGE(B7:M7),0) -> 325.53417
A8: Luz | B8: 182.43 | C8: ='Cartão de Crédito'!E6 -> 274.89 | D8: ='Cartão de Crédito'!F6 -> 419.79 | E8: ='Cartão de Crédito'!G6 -> 388.12 | F8: ='Cartão de Crédito'!H6 -> 247.5 | G8: ='Cartão de Crédito'!I6 -> 315.68 | H8: ='Cartão de Crédito'!J6 -> 257.55 | I8: ='Cartão de Crédito'!K6 -> 270.19 | J8: ='Cartão de Crédito'!L6 -> 0 | ... M8: ='Cartão de Crédito'!O6 -> 284.3 | O8: =IFERROR(AVERAGE(B8:M8),0) -> 274.51833
A9: Limpeza | B9: =220*3 -> 660 | C9: =220*2 -> 440 | D9: =220+250 -> 470 | E9: =250+250 -> 500 | F9: =250+250 -> 500 | G9: =250*3 -> 750 | H9: =250*2 -> 500 | I9: =230+250+250+250 -> 980 | J9: =250*2 -> 500 | K9: =250*2 -> 500 | L9: 750 | M9: 500 | O9: =IFERROR(AVERAGE(B9:M9),0) -> 587.5
A10: Internet | B10: 99.9 | C10: 99.9 | D10: 99.9 | E10: 99.9 | F10: 99.9 | G10: 99.9 | H10: 110.28 | I10: 110.28 | J10: 110.28 | K10: 110.28 | L10: 110.28 | M10: 110.28 | O10: =IFERROR(AVERAGE(B10:M10),0) -> 105.09
A11: Manutenção Elevador | B11: =210/2 -> 105 | C11: =210/2 -> 105 | D11: =210/2 -> 105 | E11: 105 | F11: 105 | G11: 105 | H11: 105 | I11: 105 | J11: 105 | K11: 105 | L11: 105 | M11: 105 | O11: =IFERROR(AVERAGE(B11:M11),0) -> 105
A12: Seguro Casa | D12: ='Cartão de Crédito'!F7 -> 75.98 | E12: ='Cartão de Crédito'!G7 -> 75.98 | F12: ='Cartão de Crédito'!H7 -> 75.98 | G12: ='Cartão de Crédito'!I7 -> 75.98 | H12: ='Cartão de Crédito'!J7 -> 75.98 | I12: ='Cartão de Crédito'!K7 -> 75.98 | J12: ='Cartão de Crédito'!L7 -> 75.98 | K12: ='Cartão de Crédito'!M7 -> 75.98 | ... M12: ='Cartão de Crédito'!O7 -> 75.98 | O12: =IFERROR(AVERAGE(B12:M12),0) -> 75.98
A13: Demais gastos casa | B13: ='Cartão de Crédito'!D8 -> 159.01 | D13: ='Cartão de Crédito'!F8 -> 188.14 | E13: ='Cartão de Crédito'!G8+171.9 -> 1240.69 | F13: ='Cartão de Crédito'!H8+2000 -> 4397.16 | G13: ='Cartão de Crédito'!I8+280 -> 1903.75 | H13: ='Cartão de Crédito'!J8 -> 1564.65 | I13: ='Cartão de Crédito'!K8 -> 567.76 | J13: ='Cartão de Crédito'!L8 -> 910.35 | K13: ='Cartão de Crédito'!M8 -> 1170.79 | L13: ='Cartão de Crédito'!N8 -> 2551.84 | M13: ='Cartão de Crédito'!O8 -> 2289.09 | O13: =IFERROR(AVERAGE(B13:M13),0) -> 1540.2936
A14: Total Casa | B14: =SUM(B4:B13) -> 1678.15 | C14: =SUM(C4:C13) -> 2746.76 | D14: =SUM(D4:D13) -> 3737.01 | E14: =SUM(E4:E13) -> 3735.26 | F14: =SUM(F4:F13) -> 6852.7 | G14: =SUM(G4:G13) -> 6014.87 | H14: =SUM(H4:H13) -> 4460.88 | I14: =SUM(I4:I13) -> 3894.89 | ... M14: =SUM(M4:M13) -> 3725.49 | O14: =SUM(O4:O13) -> 4301.1585
A15: Day care Farofa | C15: 368 | D15: 682 | E15: 682 | F15: 511.5 | G15: =140+682 -> 822 | H15: ='Cartão de Crédito'!J9+140 -> 822 | I15: ='Cartão de Crédito'!K9 -> 2020.52 | J15: ='Cartão de Crédito'!L9 -> 0 | K15: ='Cartão de Crédito'!M9 -> 879 | L15: ='Cartão de Crédito'!N9 -> 735.52 | M15: ='Cartão de Crédito'!O9 -> 426.25 | O15: =IFERROR(AVERAGE(B15:M15),0) -> 722.61727
A16: Adestramento Farofa | D16: =280+140 -> 420 | E16: 650 | F16: 520 | G16: 650 | H16: =420 -> 420 | I16: 560 | J16: 560 | K16: 280 | L16: 420 | M16: 700
A17: Plano de saúde | B17: 54.81 | C17: 54.81 | D17: ='Cartão de Crédito'!F10 -> 473.51 | E17: ='Cartão de Crédito'!G10 -> 170.14 | F17: ='Cartão de Crédito'!H10 -> 54.81 | G17: ='Cartão de Crédito'!I10 -> 54.81 | H17: ='Cartão de Crédito'!J10 -> 54.81 | I17: ='Cartão de Crédito'!K10 -> 54.81 | J17: ='Cartão de Crédito'!L10 -> 71.29 | K17: ='Cartão de Crédito'!M10 -> 54.81 | ... M17: ='Cartão de Crédito'!O10 -> 57.64 | O17: =IFERROR(AVERAGE(B17:M17),0) -> 102.12
A18: Demais gastos Farofa | B18: ='Cartão de Crédito'!D11 -> 338.52 | C18: ='Cartão de Crédito'!E11 -> 557.98 | D18: ='Cartão de Crédito'!F11 -> 600.27 | E18: ='Cartão de Crédito'!G11 -> 694.32 | F18: ='Cartão de Crédito'!H11 -> 677.02 | G18: ='Cartão de Crédito'!I11 -> 446.61 | H18: ='Cartão de Crédito'!J11 -> 503.81 | I18: ='Cartão de Crédito'!K11 -> 502.27 | ... M18: ='Cartão de Crédito'!O11 -> 487.37 | O18: =IFERROR(AVERAGE(B18:M18),0) -> 569.29083
A19: Total Farofa | B19: =SUM(B15:B18) -> 393.33 | C19: =SUM(C15:C18) -> 980.79 | D19: =SUM(D15:D18) -> 2175.78 | E19: =SUM(E15:E18) -> 2196.46 | F19: =SUM(F15:F18) -> 1763.33 | G19: =SUM(G15:G18) -> 1973.42 | H19: =SUM(H15:H18) -> 1800.62 | I19: =SUM(I15:I18) -> 3137.6 | ... M19: =SUM(M15:M18) -> 1671.26 | O19: =SUM(O15:O18) -> 1394.0281
A20: IPVA + licenciamento | B20: =2789.68+167.74 -> 2957.42 | O20: =IFERROR(AVERAGE(B20:M20),0) -> 2957.42
A21: Seguro Carro | E21: ='Cartão de Crédito'!G12 -> 1266.44 | F21: ='Cartão de Crédito'!H12 -> 60.85 | G21: ='Cartão de Crédito'!I12 -> 60.85 | H21: ='Cartão de Crédito'!J12 -> 60.85 | I21: ='Cartão de Crédito'!K12 -> 60.85 | J21: ='Cartão de Crédito'!L12 -> 2624.55 | K21: ='Cartão de Crédito'!M12 -> 60.85 | L21: ='Cartão de Crédito'!N12 -> 60.85 | M21: ='Cartão de Crédito'!O12 -> 60.85 | O21: =IFERROR(AVERAGE(B21:M21),0) -> 479.66
A22: Conectcar | B22: ='Cartão de Crédito'!D13+193.86 -> 343.86 | C22: ='Cartão de Crédito'!E13 -> 200 | D22: ='Cartão de Crédito'!F13 -> 50 | E22: ='Cartão de Crédito'!G13 -> 187.2 | F22: ='Cartão de Crédito'!H13 -> 200 | G22: ='Cartão de Crédito'!I13 -> 300 | H22: ='Cartão de Crédito'!J13 -> 150 | I22: ='Cartão de Crédito'!K13 -> 150 | J22: ='Cartão de Crédito'!L13 -> 116.6 | ... M22: ='Cartão de Crédito'!O13 -> 200 | O22: =IFERROR(AVERAGE(B22:M22),0) -> 191.47167
A23: Combustível | B23: ='Cartão de Crédito'!D14+110.33 -> 657.07 | C23: ='Cartão de Crédito'!E14 -> 828.28 | D23: ='Cartão de Crédito'!F14 -> 612.74 | E23: ='Cartão de Crédito'!G14 -> 1158.75 | F23: ='Cartão de Crédito'!H14 -> 756.85 | G23: ='Cartão de Crédito'!I14 -> 980.36 | H23: ='Cartão de Crédito'!J14 -> 651.17 | I23: ='Cartão de Crédito'!K14 -> 472.28 | J23: ='Cartão de Crédito'!L14 -> 1169.21 | ... M23: ='Cartão de Crédito'!O14 -> 971.77 | O23: =IFERROR(AVERAGE(B23:M23),0) -> 827.90667 | R23: Café da manhã
A24: Manutenção Carro | B24: =2000+'Cartão de Crédito'!D15 -> 5568.92 | C24: ='Cartão de Crédito'!E15 -> 2490.5 | D24: ='Cartão de Crédito'!F15 -> 152.7 | E24: ='Cartão de Crédito'!G15+750 -> 1347.7 | F24: ='Cartão de Crédito'!H15 -> 949.95 | G24: ='Cartão de Crédito'!I15 -> 1029.95 | H24: ='Cartão de Crédito'!J15 -> 877.25 | I24: ='Cartão de Crédito'!K15 -> 422.25 | J24: ='Cartão de Crédito'!L15+1000 -> 1477.5 | K24: ='Cartão de Crédito'!M15 -> 477.5 | L24: ='Cartão de Crédito'!N15 -> 397.5 | M24: ='Cartão de Crédito'!O15 -> 397.5 | O24: =IFERROR(AVERAGE(B24:M24),0) -> 1299.1017 | R24: Sábados de la do pão | S24: =60*4 -> 240
A25: Uber | B25: ='Cartão de Crédito'!D16 -> 0 | C25: ='Cartão de Crédito'!E16 -> 0 | D25: =130+'Cartão de Crédito'!F16 -> 130 | E25: ='Cartão de Crédito'!G16 -> 0 | F25: ='Cartão de Crédito'!H16+82.15 -> 318.92 | G25: ='Cartão de Crédito'!I16 -> 34.19 | H25: ='Cartão de Crédito'!J16 -> 0 | I25: ='Cartão de Crédito'!K16 -> 220.93 | J25: ='Cartão de Crédito'!L16 -> 0 | K25: ='Cartão de Crédito'!M16 -> 41.08 | L25: ='Cartão de Crédito'!N16 -> 317.14 | M25: ='Cartão de Crédito'!O16 -> 471.12 | O25: =IFERROR(AVERAGE(B25:M25),0) -> 127.78167 | R25: +1 mês | S25: 150
A26: Total Transporte | B26: =SUM(B20:B25) -> 9527.27 | C26: =SUM(C20:C25) -> 3518.78 | D26: =SUM(D20:D25) -> 945.44 | E26: =SUM(E20:E25) -> 3960.09 | F26: =SUM(F20:F25) -> 2286.57 | G26: =SUM(G20:G25) -> 2405.35 | H26: =SUM(H20:H25) -> 1739.27 | I26: =SUM(I20:I25) -> 1326.31 | ... M26: =SUM(M20:M25) -> 2101.24 | O26: =SUM(O20:O25) -> 5883.3417 | R26: Almoço
A27: Mercado | B27: ='Cartão de Crédito'!D17+289.37 -> 2109.98 | C27: ='Cartão de Crédito'!E17 -> 1115.01 | D27: ='Cartão de Crédito'!F17+225.56 -> 1036.38 | E27: ='Cartão de Crédito'!G17 -> 385.05 | F27: ='Cartão de Crédito'!H17+265.3 -> 1578.41 | G27: ='Cartão de Crédito'!I17 -> 407.62 | H27: ='Cartão de Crédito'!J17 -> 417.76 | I27: ='Cartão de Crédito'!K17 -> 163 | J27: ='Cartão de Crédito'!L17+37.82 -> 1504.64 | K27: ='Cartão de Crédito'!M17 -> 592.37 | L27: ='Cartão de Crédito'!N17 -> 394.29 | M27: ='Cartão de Crédito'!O17 -> 604.54 | O27: =IFERROR(AVERAGE(B27:M27),0) -> 859.0875 | R27: 2 por mês | S27: =200*2 -> 400
A28: Restaurante | B28: ='Cartão de Crédito'!D18 -> 1149.63 | C28: ='Cartão de Crédito'!E18 -> 1233.49 | D28: ='Cartão de Crédito'!F18+176 -> 1593.69 | E28: ='Cartão de Crédito'!G18 -> 1806.53 | F28: ='Cartão de Crédito'!H18 -> 2925.31 | G28: ='Cartão de Crédito'!I18 -> 1344 | H28: ='Cartão de Crédito'!J18 -> 1918.62 | I28: ='Cartão de Crédito'!K18 -> 2591.09 | J28: ='Cartão de Crédito'!L18 -> 2010.63 | K28: ='Cartão de Crédito'!M18 -> 722.54 | L28: ='Cartão de Crédito'!N18 -> 4309.6 | M28: ='Cartão de Crédito'!O18 -> 1189.34 | O28: =IFERROR(AVERAGE(B28:M28),0) -> 1899.5392 | R28: Jantar
A29: Ifood | B29: ='Cartão de Crédito'!D19 -> 540.67 | C29: ='Cartão de Crédito'!E19 -> 891 | D29: ='Cartão de Crédito'!F19 -> 413 | E29: ='Cartão de Crédito'!G19 -> 427.8 | F29: ='Cartão de Crédito'!H19+145.49 -> 535.98 | G29: ='Cartão de Crédito'!I19 -> 929.19 | H29: ='Cartão de Crédito'!J19 -> 1238.11 | I29: ='Cartão de Crédito'!K19 -> 456.02 | J29: ='Cartão de Crédito'!L19 -> 1142.35 | K29: ='Cartão de Crédito'!M19 -> 993.79 | L29: ='Cartão de Crédito'!N19 -> 392.26 | M29: ='Cartão de Crédito'!O19 -> 826.38 | O29: =IFERROR(AVERAGE(B29:M29),0) -> 732.2125 | R29: +1,5 por semana | S29: =120*1.5*4 -> 720
A30: Vinho | D30: 514 | F30: ='Cartão de Crédito'!H25+608.42 -> 1430.42 | G30: ='Cartão de Crédito'!I25 -> 0 | H30: ='Cartão de Crédito'!J25 -> 0 | I30: ='Cartão de Crédito'!K25 -> 0 | J30: ='Cartão de Crédito'!L25 -> 189 | K30: ='Cartão de Crédito'!M25 -> 0 | L30: ='Cartão de Crédito'!N25 -> 0 | M30: ='Cartão de Crédito'!O25 -> 0 | O30: =IFERROR(AVERAGE(B30:M30),0) -> 237.04667 | R30: +1 especial/mês | S30: 350
A31: Total Alimentação | B31: =SUM(B27:B30) -> 3800.28 | C31: =SUM(C27:C30) -> 3239.5 | D31: =SUM(D27:D30) -> 3557.07 | E31: =SUM(E27:E30) -> 2619.38 | F31: =SUM(F27:F30) -> 6470.12 | G31: =SUM(G27:G30) -> 2680.81 | H31: =SUM(H27:H30) -> 3574.49 | I31: =SUM(I27:I30) -> 3210.11 | ... M31: =SUM(M27:M30) -> 2620.26 | O31: =SUM(O27:O30) -> 3727.8858
A32: Médicos | B32: ='Cartão de Crédito'!D20 -> 0 | C32: ='Cartão de Crédito'!E20 -> 0 | D32: ='Cartão de Crédito'!F20 -> 0 | E32: ='Cartão de Crédito'!G20 -> 0 | F32: ='Cartão de Crédito'!H20 -> 0 | G32: ='Cartão de Crédito'!I20 -> 0 | H32: ='Cartão de Crédito'!J20 -> 0 | I32: ='Cartão de Crédito'!K20 -> 0 | ... M32: ='Cartão de Crédito'!O20 -> 0
A33: Farmácia | B33: ='Cartão de Crédito'!D21 -> 162.57 | C33: ='Cartão de Crédito'!E21 -> 236.04 | D33: ='Cartão de Crédito'!F21 -> 83.89 | E33: ='Cartão de Crédito'!G21 -> 525.52 | F33: ='Cartão de Crédito'!H21 -> 0 | G33: ='Cartão de Crédito'!I21 -> 0 | H33: ='Cartão de Crédito'!J21 -> 257.74 | I33: ='Cartão de Crédito'!K21 -> 284.59 | ... M33: ='Cartão de Crédito'!O21 -> 628.4 | O33: =IFERROR(AVERAGE(B33:M33),0) -> 218.77667
A34: Total Saúde | B34: =SUM(B32:B33,) -> 162.57 | C34: =SUM(C32:C33,) -> 236.04 | D34: =SUM(D32:D33,) -> 83.89 | E34: =SUM(E32:E33,) -> 525.52 | F34: =SUM(F32:F33,) -> 0 | G34: =SUM(G32:G33,) -> 0 | H34: =SUM(H32:H33,) -> 257.74 | I34: =SUM(I32:I33,) -> 284.59 | ... M34: =SUM(M32:M33,) -> 628.4 | O34: =SUM(O33) -> 218.77667
A35: Viagem | B35: ='Cartão de Crédito'!D22+570 -> 4601.76 | C35: ='Cartão de Crédito'!E22 -> 2674.5267 | D35: =71.4+'Cartão de Crédito'!F22 -> 568.17 | E35: ='Cartão de Crédito'!G22 -> 3612.29 | F35: ='Cartão de Crédito'!H22+326 -> 7830.96 | G35: ='Cartão de Crédito'!I22 -> 3897.95 | H35: ='Cartão de Crédito'!J22 -> 2821.89 | I35: ='Cartão de Crédito'!K22 -> 1732.85 | J35: ='Cartão de Crédito'!L22 -> 2383.46 | K35: ='Cartão de Crédito'!M22 -> 3747.77 | L35: ='Cartão de Crédito'!N22 -> 4181.8 | M35: ='Cartão de Crédito'!O22 -> 3713.29 | O35: =IFERROR(AVERAGE(B35:M35),0) -> 3480.5597
A36: Lazer | B36: ='Cartão de Crédito'!D23 -> 0 | C36: ='Cartão de Crédito'!E23 -> 1205 | D36: ='Cartão de Crédito'!F23+40 -> 147 | E36: ='Cartão de Crédito'!G23 -> 437.19 | F36: ='Cartão de Crédito'!H23 -> 703.2 | G36: ='Cartão de Crédito'!I23 -> 459 | H36: ='Cartão de Crédito'!J23+150 -> 394 | I36: ='Cartão de Crédito'!K23 -> 346 | J36: ='Cartão de Crédito'!L23 -> 1084.36 | K36: ='Cartão de Crédito'!M23 -> 0 | L36: ='Cartão de Crédito'!N23 -> 160 | M36: ='Cartão de Crédito'!O23 -> 534.75 | O36: =IFERROR(AVERAGE(B36:M36),0) -> 455.875
A37: Total Lazer | B37: =SUM(B35:B36) -> 4601.76 | C37: =SUM(C35:C36) -> 3879.5267 | D37: =SUM(D35:D36) -> 715.17 | E37: =SUM(E35:E36) -> 4049.48 | F37: =SUM(F35:F36) -> 8534.16 | G37: =SUM(G35:G36) -> 4356.95 | H37: =SUM(H35:H36) -> 3215.89 | I37: =SUM(I35:I36) -> 2078.85 | ... M37: =SUM(M35:M36) -> 4248.04 | O37: =SUM(O35:O36) -> 3936.4347
A38: Bebê | B38: ='Cartão de Crédito'!D26 -> 0 | C38: ='Cartão de Crédito'!E26 -> 0 | D38: ='Cartão de Crédito'!F26 -> 0 | E38: ='Cartão de Crédito'!G26 -> 0 | F38: ='Cartão de Crédito'!H26 -> 0 | G38: ='Cartão de Crédito'!I26 -> 0 | H38: ='Cartão de Crédito'!J26 -> 0 | I38: ='Cartão de Crédito'!K26 -> 0 | ... M38: ='Cartão de Crédito'!O26 -> 958.88
A39: Outras despesas | B39: ='Cartão de Crédito'!D27+'Cartão de Crédito'!D24 -> 200 | C39: ='Cartão de Crédito'!E27+'Cartão de Crédito'!E24 -> 0 | D39: ='Cartão de Crédito'!F27+'Cartão de Crédito'!F24 -> 0 | E39: ='Cartão de Crédito'!G27+'Cartão de Crédito'!G24 -> 468.52 | F39: ='Cartão de Crédito'!H27++'Cartão de Crédito'!H24 -> 159.28 | G39: ='Cartão de Crédito'!I27+300+300+'Cartão de Crédito'!I24 -> 624.12 | H39: ='Cartão de Crédito'!J27+458.72+'Cartão de Crédito'!J24 -> 530.57 | I39: ='Cartão de Crédito'!K27++'Cartão de Crédito'!K24 -> 750.81 | J39: ='Cartão de Crédito'!L27++'Cartão de Crédito'!L24+24.2+55 -> 295.6 | K39: ='Cartão de Crédito'!M27++'Cartão de Crédito'!M24 -> 0 | L39: ='Cartão de Crédito'!N27++'Cartão de Crédito'!N24 -> 652.75 | M39: ='Cartão de Crédito'!O27++'Cartão de Crédito'!O24 -> 2433.81 | O39: =IFERROR(AVERAGE(B39:M39),0) -> 509.62167
A40: Empréstimo Casa | B40: 7916.6667 | C40: 7916.6667 | D40: 7916.6667 | E40: 7916.6667 | F40: 7916.6667 | G40: 7916.6667 | H40: 7916.6667 | I40: 7916.6667 | J40: 7916.6667 | K40: 7916.6667 | L40: 7916.6667 | M40: 7916.6667 | O40: =IFERROR(AVERAGE(B40:M40),0) -> 7916.6667
...

Sheet Comparativo
A1: Comparativo 2025
B3: 45681 | C3: 45712 | D3: 45740 | E3: 45771 | F3: 45801 | G3: 45832 | H3: 45862 | I3: 45893 | J3: 45924 | K3: 45954 | L3: 45985 | M3: 46015
A4: Total Casa | B4: ='2025'!B14/'2025'!B$42 -> 0.059340467 | C4: ='2025'!C14/'2025'!C$42 -> 0.12198029 | D4: ='2025'!D14/'2025'!D$42 -> 0.19533766 | E4: ='2025'!E14/'2025'!E$42 -> 0.14664539 | F4: ='2025'!F14/'2025'!F$42 -> 0.20165185 | G4: ='2025'!G14/'2025'!G$42 -> 0.23158889 | H4: ='2025'!H14/'2025'!H$42 -> 0.18985597 | I4: ='2025'!I14/'2025'!I$42 -> 0.17234159 | ... M4: ='2025'!M14/'2025'!M$42 -> 0.14699016
A5: Total Farofa | B5: ='2025'!B19/'2025'!B$42 -> 0.013908403 | C5: ='2025'!C19/'2025'!C$42 -> 0.0435557 | D5: ='2025'!D19/'2025'!D$42 -> 0.11373044 | E5: ='2025'!E19/'2025'!E$42 -> 0.086232481 | F5: ='2025'!F19/'2025'!F$42 -> 0.051888856 | G5: ='2025'!G19/'2025'!G$42 -> 0.075982051 | H5: ='2025'!H19/'2025'!H$42 -> 0.076634759 | I5: ='2025'!I19/'2025'!I$42 -> 0.13883292 | ... M5: ='2025'!M19/'2025'!M$42 -> 0.065939989
A6: Total Transporte | B6: ='2025'!B26/'2025'!B$42 -> 0.33689042 | C6: ='2025'!C26/'2025'!C$42 -> 0.15626477 | D6: ='2025'!D26/'2025'!D$42 -> 0.049419198 | E6: ='2025'!E26/'2025'!E$42 -> 0.15547216 | F6: ='2025'!F26/'2025'!F$42 -> 0.067286045 | G6: ='2025'!G26/'2025'!G$42 -> 0.092612533 | H6: ='2025'!H26/'2025'!H$42 -> 0.07402369 | I6: ='2025'!I26/'2025'!I$42 -> 0.058686733 | ... M6: ='2025'!M26/'2025'!M$42 -> 0.082904959
A7: Total Alimentação | B7: ='2025'!B31/'2025'!B$42 -> 0.13438035 | C7: ='2025'!C31/'2025'!C$42 -> 0.14386228 | D7: ='2025'!D31/'2025'!D$42 -> 0.185932 | E7: ='2025'!E31/'2025'!E$42 -> 0.10283622 | F7: ='2025'!F31/'2025'!F$42 -> 0.19039381 | G7: ='2025'!G31/'2025'!G$42 -> 0.10321849 | H7: ='2025'!H31/'2025'!H$42 -> 0.15213103 | I7: ='2025'!I31/'2025'!I$42 -> 0.14204135 | ... M7: ='2025'!M31/'2025'!M$42 -> 0.10338303
A8: Total Saúde | B8: ='2025'!B34/'2025'!B$42 -> 0.0057485802 | C8: ='2025'!C34/'2025'!C$42 -> 0.010482251 | D8: ='2025'!D34/'2025'!D$42 -> 0.0043850234 | E8: ='2025'!E34/'2025'!E$42 -> 0.020631786 | F8: ='2025'!F34/'2025'!F$42 -> 0 | G8: ='2025'!G34/'2025'!G$42 -> 0 | H8: ='2025'!H34/'2025'!H$42 -> 0.010969468 | I8: ='2025'!I34/'2025'!I$42 -> 0.012592574 | ... M8: ='2025'!M34/'2025'!M$42 -> 0.024793682
A9: Total Lazer | B9: ='2025'!B37/'2025'!B$42 -> 0.1627212 | C9: ='2025'!C37/'2025'!C$42 -> 0.17228509 | D9: ='2025'!D37/'2025'!D$42 -> 0.03738273 | E9: ='2025'!E37/'2025'!E$42 -> 0.15898159 | F9: ='2025'!F37/'2025'!F$42 -> 0.25113155 | G9: ='2025'!G37/'2025'!G$42 -> 0.16775445 | H9: ='2025'!H37/'2025'!H$42 -> 0.13686894 | I9: ='2025'!I37/'2025'!I$42 -> 0.091985219 | ... M9: ='2025'!M37/'2025'!M$42 -> 0.1676075
A10: Outras despesas | B10: ='2025'!B39/'2025'!B$42 -> 0.0070721291 | C10: ='2025'!C39/'2025'!C$42 -> 0 | D10: ='2025'!D39/'2025'!D$42 -> 0 | E10: ='2025'!E39/'2025'!E$42 -> 0.01839398 | F10: ='2025'!F39/'2025'!F$42 -> 0.0046870733 | G10: ='2025'!G39/'2025'!G$42 -> 0.024030322 | H10: ='2025'!H39/'2025'!H$42 -> 0.022581169 | I10: ='2025'!I39/'2025'!I$42 -> 0.033221936 | ... M10: ='2025'!M39/'2025'!M$42 -> 0.096026593
A11: Empréstimo Casa | B11: ='2025'!B40/'2025'!B$42 -> 0.27993844 | C11: ='2025'!C40/'2025'!C$42 -> 0.35156961 | D11: ='2025'!D40/'2025'!D$42 -> 0.41381295 | E11: ='2025'!E40/'2025'!E$42 -> 0.31080639 | F11: ='2025'!F40/'2025'!F$42 -> 0.23296081 | G11: ='2025'!G40/'2025'!G$42 -> 0.30481325 | H11: ='2025'!H40/'2025'!H$42 -> 0.33693497 | I11: ='2025'!I40/'2025'!I$42 -> 0.35029767 | ... M11: ='2025'!M40/'2025'!M$42 -> 0.3123541
A12: TOTAL | B12: =SUM(B4:B11) -> 1 | C12: =SUM(C4:C11) -> 1 | D12: =SUM(D4:D11) -> 1 | E12: =SUM(E4:E11) -> 1 | F12: =SUM(F4:F11) -> 1 | G12: =SUM(G4:G11) -> 1 | H12: =SUM(H4:H11) -> 1 | I12: =SUM(I4:I11) -> 1 | ... M12: =SUM(M4:M11) -> 1

Sheet Cartão de Crédito
A1: Gastos cartão de crédito
G2: água | H2: água | I2: água
A3: *Atualizado até 31/10 | G3: 407.87 | H3: 528.31 | I3: 588.53
B4: 45620 | C4: 45650 | D4: 45681 | E4: 45712 | F4: 45740 | G4: 45771 | H4: 45801 | I4: 45832 | J4: 45862 | K4: 45893 | L4: 45924 | M4: 45954 | N4: 45985 | O4: 46015 | P4: 46046 | Q4: 46077 | R4: 46105
A5: Água | F5: =536.93+G3 -> 944.8 | J5: 258.84 | K5: 278.83 | L5: 319.53 | N5: 174.93 | O5: 131.29
A6: Luz | E6: 274.89 | F6: 419.79 | G6: 388.12 | H6: 247.5 | I6: 315.68 | J6: 257.55 | K6: =270.19 -> 270.19 | M6: =317.21+336.56 -> 653.77 | O6: 284.3
A7: Seguro Casa | F7: =75.98 -> 75.98 | G7: =F7 -> 75.98 | H7: =G7 -> 75.98 | I7: 75.98 | J7: 75.98 | K7: 75.98 | L7: 75.98 | M7: 75.98 | N7: 75.98 | O7: 75.98
A8: Demais gastos casa | B8: =112.93+62.38 -> 175.31 | C8: 88.64 | D8: =69.37+24.9+17.86+46.88 -> 159.01 | F8: 188.14 | G8: =215.62+314.95+319.87+20-0.02-448+222.78+89.9+333.69 -> 1068.79 | H8: =215.62+314.95+222.78-629.9-0.04+209.98+90.59+567.76+297.74+387+332.74+187.63+220+193.89+215.26-206.06-222.78 -> 2397.16 | I8: =215.62+209.98+567.76-0.03+297.74-0.02+332.74-0.04 -> 1623.75 | J8: =209.98+567.76+297.74+332.74+156.43 -> 1564.65 | K8: =567.76 -> 567.76 | L8: =735.15+175.2 -> 910.35 | M8: =41.4+187.89+99.8+961.7-120 -> 1170.79 | N8: =961.7+164.95+1000+26.49+119.9+19+119.9+139.9 -> 2551.84 | O8: =961.7+164.95+1000+43.49+118.95 -> 2289.09 | P8: =961.7+1000 -> 1961.7 | Q8: =961.7+1000 -> 1961.7 | R8: =961.7+1000 -> 1961.7
A9: Day Care Farofa | J9: 682 | K9: =682+1141.52+197 -> 2020.52 | M9: 879 | N9: 735.52 | O9: 426.25
A10: Plano de saúde Farofa | F10: =197.72+10.98+54.81+210 -> 473.51 | G10: =54.81+82.38+32.95 -> 170.14 | H10: 54.81 | I10: 54.81 | J10: 54.81 | K10: 54.81 | L10: =54.81+16.48 -> 71.29 | M10: 54.81 | N10: =11.55+57.64 -> 69.19 | O10: 57.64
A11: Demais gastos Farofa | B11: =45.9+334.22+77.9 -> 458.02 | C11: =129.18+299.16+56.17+22.8+10.98 -> 518.29 | D11: =239.16+99.36 -> 338.52 | E11: =399.37+108.35+27.46+22.8 -> 557.98 | F11: =10.98+42.79+19.47+111.21+415.82 -> 600.27 | G11: =139.9+26.6+94.91+103.45+288.61+40.85 -> 694.32 | H11: =94.9+40.85+214.85+57+269.42 -> 677.02 | I11: =25.65+9.99+303.92+107.05 -> 446.61 | J11: =9.99+16.9+322.92+154 -> 503.81 | K11: =60.42+324.81+9.99+107.05 -> 502.27 | L11: =9.99+159.07+153.91+325.82+88.22 -> 737.01 | M11: =9.99+27.46+265.57+324.81 -> 627.83 | N11: =19.95+120.27+173.8+11.55+322.92+9.99 -> 658.48 | O11: =11.55+34.65+9.99+431.18 -> 487.37 | P11: 9.99 | Q11: 9.99 | R11: 9.99 | S11: 9.99 | T11: 9.99
A12: Seguro Carro | G12: =1205.59+60.85 -> 1266.44 | H12: 60.85 | I12: 60.85 | J12: 60.85 | K12: 60.85 | L12: =60.85+2563.7 -> 2624.55 | M12: 60.85 | N12: 60.85 | O12: 60.85
A13: Conectcar | B13: 26 | D13: =50*3 -> 150 | E13: =100+50+50 -> 200 | F13: 50 | G13: =50+50+13+12.8+11.4+50 -> 187.2 | H13: =100+50+50 -> 200 | I13: =50+50+50+50+50+50 -> 300 | J13: =50+50+50 -> 150 | K13: =50*3 -> 150 | L13: =13.6*2+12.1+50+13.7+13.6 -> 116.6 | M13: =50*3+100 -> 250 | N13: =50+50+50 -> 150 | O13: =50+50+50+50 -> 200
A14: Combustível | B14: =151.44+131.9+170.23+144.02+174.2 -> 771.79 | C14: =253.49+175.01+171 -> 599.5 | D14: =297.08+249.66 -> 546.74 | E14: =264.81+211.91+195.88+155.68 -> 828.28 | F14: =241.9+174.43+196.41 -> 612.74 | G14: =275.03+101.8+283.39+257.63+240.9 -> 1158.75 | H14: =249.69+253.15+254.01 -> 756.85 | I14: =247.83+260.62+254.39+217.52 -> 980.36 | J14: =228.99+200.04+222.14 -> 651.17 | K14: =224.21+10+238.07 -> 472.28 | L14: =116.28+115.63+219.92+201.89+275.58+239.91 -> 1169.21 | M14: =237.71+269.12+262.4+253.08 -> 1022.31 | N14: =245.89+187.95+220.25 -> 654.09 | O14: =256.74+240.2+224.83+250 -> 971.77
A15: Manutenção Carro | B15: 928.22 | C15: =2433.02+70+928.22 -> 3431.24 | D15: =152.7+30+2338+120+928.22 -> 3568.92 | E15: =2338+152.5 -> 2490.5 | F15: =152.7 -> 152.7 | G15: =F15+70+375 -> 597.7 | H15: =F15+375+422.25 -> 949.95 | I15: =F15+375+422.25+80 -> 1029.95 | J15: =375+422.25+80 -> 877.25 | K15: =422.25 -> 422.25 | L15: =80+397.5 -> 477.5 | M15: =397.5+80 -> 477.5 | N15: 397.5 | O15: 397.5
A16: Uber | C16: =17.33+75.24+68.68+37.16+36.56+39.36+20.22+41.98+33.05+29.53 -> 399.11 | H16: =87.28+21.25+22.63+105.61 -> 236.77 | I16: =34.19 -> 34.19 | K16: =40.75+36.12+22.24+18.66+30.52+24.68+47.96 -> 220.93 | M16: =41.08 -> 41.08 | N16: =65.52+15.73+11.65+21.8+30.55+12.31+16.48+8.99+12.98+19.93+6.3+36.96+57.94 -> 317.14 | O16: =128.43+23.98+33.95+33.47+28.99+33.92+40.98+147.4 -> 471.12
A17: Mercado | B17: =438.72+23.73+22.24+21.86+19.57+144.23+36.26+58.87+27.56 -> 793.04 | C17: =21.92+1.1+41.35+132.98+4.05+35+43.16+25.64 -> 305.2 | D17: =101.02+40.76+13+12+12+38+4+143.38+38.48+32.29+534.55+5+41.8+14.3+18+6.6+86.48+23.84+28.36+93.57+44.41+20.08+300.89+18.59+7.98+92.53+48.7 -> 1820.61 | E17: =38+6+38+8+16+8+10+7+40.97+2+27+91.2+10+42.5+38+187.74+86.77+47.95+409.88 -> 1115.01 | F17: =6+25+2.8+38+159.53+27.98+16.99+8+48+290.56+10+22.04+155.92 -> 810.82 | G17: =50+35+30+159.47+23.85+40+42.23+4.5 -> 385.05 | H17: =51.16+21.65+198.46+291.08+40+502.17+208.59 -> 1313.11 | I17: =20+1.59+188.16+40+38.69+79.18+40 -> 407.62 | J17: =169.6+80.82+60+15.9+29.04+28.48+33.92 -> 417.76 | K17: =43.04+40+56.01+23.95 -> 163 | L17: =95+474.25+40+218.22+30+24.9+48.8+263.15+85.74+75.46+51.3+60 -> 1466.82 | M17: =16+67.6+50.02+30.31+40+10+14.7+580.52-144.53-72.25 -> 592.37 | N17: =40+7+15+71.88+260.41 -> 394.29 | O17: =157.25+348.36+22.52+34.73+41.68 -> 604.54
A18: Restaurante | B18: =221.65+304.4+104+53.7+81.7+110+235.77+232.68+53.7+53.6+82 -> 1533.2 | C18: =85.9+126.56+302.83+109.45+202.4+429.4+40+62.5+261.4+83.7+147+32.85+98.7+26.18+55.8 -> 2064.67 | D18: =91.08+457.81+26+187.04+81.7+57.2+18.9+49.4+10.5+118+52 -> 1149.63 | E18: =14.9+40.5+79.08+40.5+34.2+155.1+352.56+333.85+63.8+90+29 -> 1233.49 | F18: =54.1+40.5+45+15.05+397.3+18.9+40.5+136.73+122.75+211.7+25.99+192.78+113.55+2.84 -> 1417.69 | G18: =517+39.16+183.7+40.5+202.27+101.39+64.9+66+25.7+55.1+53.11+108+49.5+20.9+126.8+133.1+19.4 -> 1806.53 | H18: =45.93+47.3+101.57+59.3+47+194+418+40.5+25.2+828+71.75+210.18+55.25+27+358.4+90.2+189.73+116 -> 2925.31 | I18: =44.7+36.45+72.73+45+103.4+217.69+89.99+36.5+305+51.3+27.08+52+39.11+55.5+94.5+73.05 -> 1344 | J18: =87.73+44.5+368.94+48.1+160.7+173.6+514.15+63.9+37.2+219.89+64.11+47+51.3+37.5 -> 1918.62 | K18: =131+18+67+27.96+487.42+151.5+15.15+159.48+167+214.5+100.26+170+52.11+70.08+163.3+57+102.4+63.93+12+292+69 -> 2591.09 | L18: =204.43+106.3+29.2+819.9+45+60.7+99.5+149.16+102.7+99.5+82.72+111.7+99.82 -> 2010.63 | M18: =43.84+26.04+81.9+109+12+140+64.56+25+57.7+67.19+46.31+49 -> 722.54 | N18: =44.5+106.1+24.9+76+21.14+27.5+151+95.26+457.49+319.9+12+227.7+33.81+25.4+30+297.8+119.9+259.6+168.3+174.9+229.9+53+247.6+8+24.7+20+58+450+184.8+3+20+211.2+76.2+42+8 -> 4309.6 | O18: =162.91+16+123.2+154.34+269.5+178.03+84.3+101.06+100 -> 1189.34
A19: Ifood | B19: =137.7+102.9+93.89+185.5+140.89 -> 660.88 | C19: =153+1.75+84.36+117.69+154.79+79.4+123.3+109+86.9+31.15+14+32.8 -> 988.14 | D19: =123.7+67.99+66.89+121.7+63.89+96.5 -> 540.67 | E19: =226+83.8+93.7+161.9+244.8+80.8 -> 891 | F19: =108.8+83.2+105+116 -> 413 | G19: =91.01+142.89+80+113.9 -> 427.8 | H19: =124.61+159+106.88 -> 390.49 | I19: =69.79+69.68+210.69+16.99+109.79+119.99+124.78+98.99+108.49 -> 929.19 | J19: =45.98+80+193.89+60.18+100.8+236.89+181.16+69.68+39.59+130.65+99.29 -> 1238.11 | K19: =130.66+155.78+146.99+22.59 -> 456.02 | L19: =115.28+150.78+201.66+106.79+104.79+73.08+129.59+111.22+149.16 -> 1142.35 | M19: =214.59+109.11+111.22+105.48+352+253.49-101.4-50.7 -> 993.79 | N19: =72.89+101.78+217.59 -> 392.26 | O19: =249.6+219.59+97.7+259.49 -> 826.38
A20: Médicos | M20: 580 | N20: =159+300+350 -> 809
A21: Farmácia | B21: =3.99+148.84+29.98 -> 182.81 | C21: =6.72+30.48+11.12 -> 48.32 | D21: 162.57 | E21: =116.54+119.5 -> 236.04 | F21: =83.89 -> 83.89 | G21: =178.54+346.98 -> 525.52 | J21: =49.75+207.99 -> 257.74 | K21: =71.8+171.21+41.58 -> 284.59 | M21: =6.98+217.56 -> 224.54 | N21: =22.2+59.47+27.96+112.4 -> 222.03 | O21: =112.4+206.89+57.44+251.67 -> 628.4
A22: Viagem | B22: =2532.44+305.35+1289.46+1312.73+1128.4+847.8*2 -> 8263.98 | C22: =1128.4+486.1+320.08 -> 1934.58 | D22: =4834.48/2+486.12+1128.4 -> 4031.76 | E22: =(7761.27+262.31)/3 -> 2674.5267 | F22: 496.77 | G22: =496.77-0.06+200.98+2914.6 -> 3612.29 | H22: =496.77+200.9+2914.6+504.17+2143.65+196.23+468.59+22.63+21.25+87.28+105.61+53.37+261.25+28.66 -> 7504.96 | I22: =496.77+200.98+2914.6+285.6 -> 3897.95 | J22: =200.98+3714.25-1392.84+599-299.5 -> 2821.89 | K22: =200.98+397.76+538.56+395.55+200 -> 1732.85 | L22: =397.76+395.55+1590.15 -> 2383.46 | M22: =397.76+395.55+739.97+149.9+67.28+487.46+427.9+159.32+185.06+737.57 -> 3747.77 | N22: =397.76+395.55+739.97+149.9+487.46+427.9+159.32+737.57+467.02+219.35 -> 4181.8 | O22: =739.97+427.9+737.57+467.02+1299.83+41 -> 3713.29 | P22: =427.9+737.57+467.02 -> 1632.49
A23: Lazer | E23: =324+160*2+385+176 -> 1205 | F23: =51+31+25 -> 107 | G23: =14+63.54+9.65+350 -> 437.19 | H23: =637.2+66 -> 703.2 | I23: =40+179+15+50+155+9+11 -> 459 | J23: =244 -> 244 | K23: =244+42+60 -> 346 | L23: =494.36+590 -> 1084.36 | N23: =100+60 -> 160 | O23: =324+15.25+24+171.5 -> 534.75
A24: Presentes | C24: =500.24+73 -> 573.24 | G24: =298.54+169.98 -> 468.52 | H24: =105.91+53.37 -> 159.28 | K24: =229.99+63.82+27.8 -> 321.61 | L24: =204 -> 204 | N24: =157.23+89.8+55+351 -> 653.03 | O24: =157.23+389.7+259.8+305.09+131.5+289.98+299.8+109.9+159.99+89.9 -> 2192.89 | P24: =131.5+289.98 -> 421.48
A25: Vinhos | H25: =220*3+162 -> 822 | L25: =189 -> 189
A26: Bebê | N26: =369.99 -> 369.99 | O26: =22.9+164.99+300+350+120.99 -> 958.88 | P26: 164.99
A27: Outras despesas | B27: =12+4068.7+369.86+43.8 -> 4494.36 | C27: 48.29 | D27: =56*2+88 -> 200 | I27: =25.12-1 -> 24.12 | J27: =71.85 -> 71.85 | K27: =60+156.65+212.55 -> 429.2 | L27: =10+2.4 -> 12.4 | N27: -0.28 | O27: =80.97+8+55+12+50+35-0.05 -> 240.92
A28: Total Cartão | B28: =SUM(B5:B27) -> 18287.61 | C28: =SUM(C5:C27) -> 10999.22 | D28: =SUM(D5:D27) -> 12668.43 | E28: =SUM(E5:E27) -> 11706.717 | F28: =SUM(F5:F27) -> 6847.1 | G28: =SUM(G5:G27) -> 13270.34 | H28: =SUM(H5:H27) -> 19475.24 | I28: =SUM(I5:I27) -> 11984.06 | ... R28: =SUM(R5:R27) -> 1971.69
A30: Outros (reembolso) | D30: =4834.48/2+86.9 -> 2504.14 | E30: =(7761.27+262.31)/3*2 -> 5349.0533 | G30: 630.96 | J30: =1392.84+299.5 -> 1692.34 | M30: =119.97+152.1+216.78 -> 488.85
A32: Total Visa | D32: 13454.02 | E32: 16748.97 | F32: 5485.36 | G32: 10266.84 | H32: 15429.54 | I32: 8507.9 | J32: 13534.43 | K32: 10887.39 | L32: 13515.15 | M32: 12190.55 | N32: 16391.04 | O32: 14516.08
A33: Total Master | D33: 1718.55 | E33: 306.8 | F33: 1361.74 | G33: 3634.46 | H33: 4045.7 | I33: 3476.16 | J33: 264.79 | K33: 533.64 | L33: 1479.89 | M33: 473.23 | N33: 946.2 | O33: 2226.47
A34: Total Cartões | D34: =SUM(D32:D33) -> 15172.57 | E34: =SUM(E32:E33) -> 17055.77 | F34: =SUM(F32:F33) -> 6847.1 | G34: =SUM(G32:G33) -> 13901.3 | H34: =SUM(H32:H33) -> 19475.24 | I34: =SUM(I32:I33) -> 11984.06 | J34: =SUM(J32:J33) -> 13799.22 | K34: =SUM(K32:K33) -> 11421.03 | ... R34: =SUM(R32:R33) -> 0
A36: Check final | D36: =D28+D30-SUM(D32:D33) -> 0 | E36: =E28+E30-SUM(E32:E33) -> 0 | F36: =F28+F30-SUM(F32:F33) -> 0 | G36: =G28+G30-SUM(G32:G33) -> 0 | H36: =H28+H30-SUM(H32:H33) -> 0 | I36: =I28+I30-SUM(I32:I33) -> 0 | J36: =J28+J30-SUM(J32:J33) -> 0 | K36: =K28+K30-SUM(K32:K33) -> 0 | ... R36: =R28+R30-SUM(R32:R33) -> 1971.69

Sheet Histórico contas
A1: Contas dos xuxus
A3: Conta | B3: 44562 | C3: 44593 | D3: 44621 | E3: 44652 | F3: 44682 | G3: 44713 | H3: 44743 | I3: 44774 | J3: 44805 | K3: 44835 | L3: 44866 | M3: 44896 | N3: 44927 | O3: 44958 | P3: 44986 | Q3: 45017 | R3: 45047 | S3: 45078 | T3: 45108 | U3: 45139 | V3: 45170 | W3: 45200 | X3: 45231 | Y3: 45261 | Z3: 45292 | AA3: 45346 | AB3: 45375 | AC3: 45406 | AD3: 45436 | AE3: 45467 | AF3: 45497 | AG3: 45528 | AH3: 45559 | AI3: 45589 | AJ3: 45620 | AK3: 45650 | AL3: 45681 | AM3: 45712 | AN3: 45740 | AO3: 45771 | AQ3: Média Gastos 2024
A4: IPTU | B4: 0 | C4: 331.62 | D4: 331.62 | E4: 331.62 | F4: 331.62 | G4: 331.62 | H4: 331.62 | I4: 331.62 | J4: 331.62 | K4: 331.62 | L4: 331.62 | O4: 350.82 | P4: 350.82 | Q4: 350.82 | R4: 350.82 | S4: 350.82 | T4: 350.82 | Y4: =767.27+389.78 -> 1157.05 | AA4: 827.42 | AB4: 827.42 | AC4: 827.42 | AD4: 827.42 | AE4: 827.42 | AF4: 827.42 | AG4: 827.42 | AH4: 827.42 | AI4: 827.42 | AJ4: 827.42 | AM4: 910.16 | AN4: 910.16 | AO4: 910.16 | AQ4: =SUM(Z4:AK4)/12 -> 689.51667
A5: Condomínio | B5: 985.97 | C5: 948.24 | D5: 957.83 | E5: 1127.48 | F5: 1150.4 | G5: 1200.87 | H5: 1191.62 | I5: 1177.43 | J5: 1149.46 | K5: 1148.46 | L5: 1076.82 | M5: 1146.82 | N5: 1156.66 | O5: 1188.46 | P5: 1091.59 | Q5: 1225.43 | R5: 1234.33 | S5: 1307.32 | T5: 1347.48 | W5: 150 | X5: 150 | Y5: 150 | Z5: 150 | AA5: 150 | AB5: 150 | AC5: 150 | AD5: 150 | AE5: 150 | AF5: 150 | AG5: 150 | AH5: 150 | AI5: 150 | AJ5: 150 | AK5: 150 | AL5: 150 | AM5: 150 | AN5: 150 | AO5: 150 | AQ5: =SUM(Z5:AK5)/12 -> 150
A6: Água | V6: 100.88 | W6: 74.36 | X6: 72.05 | Y6: 72.05 | Z6: 72.05 | AA6: 72.05 | AB6: 76.89 | AC6: 72.05 | AD6: 185.02 | AE6: 178.95 | AF6: 318.3 | AG6: 438.7 | AH6: 148.78 | AI6: 197.1 | AJ6: 257.32 | AK6: 115.07 | AL6: 377.76 | AQ6: =SUM(Z6:AK6)/12 -> 177.69
A7: Gás | V7: 59.56 | W7: 128.25 | X7: 169.63 | Y7: 185.67 | Z7: 179.23 | AA7: 207.14 | AB7: 278.75 | AC7: 236.93 | AD7: 264.4 | AE7: 184.19 | AF7: 272.34 | AG7: 221.72 | AH7: 303.28 | AI7: 383.69 | AJ7: 189.94 | AK7: 313.51 | AL7: 206.74 | AM7: 389.05 | AN7: 373.24 | AQ7: =SUM(Z7:AK7)/12 -> 252.92667
A8: Luz | B8: 74.28 | C8: 101.18 | D8: 94.9 | E8: 97.6 | F8: 74.25 | G8: 55.25 | H8: 77.27 | I8: 64.1 | J8: 52.38 | K8: 81.01 | L8: 81.46 | M8: 100.52 | N8: 87.09 | O8: 103.03 | P8: 100.65 | Q8: 105.37 | R8: 92.78 | S8: 81.61 | T8: 83.96 | U8: 55.55 | V8: 97.94 | W8: 126.54 | X8: 96.92 | Y8: 205.13 | Z8: 218.88 | AA8: 231.61 | AB8: 505.82 | AC8: 289.38 | AD8: 215.02 | AE8: 233.02 | AF8: 235.07 | AG8: 208.01 | AH8: 204.89 | AI8: 230.63 | AJ8: 201.27 | AK8: 182.43 | AL8: 274.89 | AM8: 412.45 | AQ8: =SUM(Z8:AK8)/12 -> 246.33583
A9: Aluguel vaga | B9: 200 | C9: 200 | D9: 200 | E9: 200 | F9: 200 | G9: 250 | H9: 250 | I9: 250 | J9: 250 | K9: 250 | L9: 250 | AQ9: =SUM(Z9:AK9)/12 -> 0
A10: Limpeza | B10: =150+120 -> 270 | C10: 150 | D10: 300 | E10: 300 | F10: 300 | G10: 300 | H10: 450 | I10: 250 | J10: 300 | K10: 300 | L10: 300 | M10: 300 | N10: 150 | O10: 300 | P10: 600 | Q10: 600 | R10: 600 | S10: =150*5 -> 750 | T10: =200+200 -> 400 | U10: 200 | V10: =200+220+220+220 -> 860 | W10: =220*3 -> 660 | X10: =220*4 -> 880 | Y10: =220*3 -> 660 | Z10: =220*4 -> 880 | AA10: =220*4 -> 880 | AB10: =220*3 -> 660 | AC10: =220*3 -> 660 | AD10: =220*3 -> 660 | AE10: =220*2 -> 440 | AF10: 220 | AG10: =220*4 -> 880 | AH10: =220*3 -> 660 | AI10: =220*4 -> 880 | AJ10: =220*2 -> 440 | AK10: =220*2 -> 440 | AL10: =220*3 -> 660 | AQ10: =SUM(Z10:AK10)/12 -> 641.66667
A11: Internet | B11: 161.86 | C11: 161.86 | D11: 161.86 | E11: 161.86 | F11: 161.86 | G11: 161.86 | H11: 161.86 | I11: 161.86 | J11: 140.82 | K11: 140.81 | L11: 151.9 | M11: 151.9 | N11: 151.83 | O11: 150.94 | P11: 151.5 | Q11: 150.08 | R11: 151.9 | S11: 151.9 | T11: 151.9 | U11: 193.14 | V11: 99.9 | W11: 99.9 | X11: 99.9 | Y11: 99.9 | Z11: 99.9 | AA11: 99.9 | AB11: 99.9 | AC11: 99.9 | AD11: 99.9 | AE11: 99.9 | AF11: 99.9 | AG11: 99.9 | AH11: 99.9 | AI11: 99.9 | AJ11: 99.9 | AK11: 99.9 | AL11: 99.9 | AM11: 99.9 | AN11: 99.9 | AQ11: =SUM(Z11:AK11)/12 -> 99.9
A12: Demais gastos casa | B12: 0 | F12: 739 | H12: 253 | J12: =220.83+382 -> 602.83 | K12: =226.8+179.09 -> 405.89 | L12: =214.8+76.46 -> 291.26 | M12: 850 | N12: 2465.47 | Q12: =1159+1484.25 -> 2643.25 | V12: =891+430 -> 1321 | W12: =400+241.47 -> 641.47 | X12: =475+2289 -> 2764 | Z12: =3497+800 -> 4297 | AQ12: =SUM(Z12:AK12)/12 -> 358.08333
A13: Total Casa | B13: =SUM(B4:B12) -> 1692.11 | C13: =SUM(C4:C12) -> 1892.9 | D13: =SUM(D4:D12) -> 2046.21 | E13: =SUM(E4:E12) -> 2218.56 | F13: =SUM(F4:F12) -> 2957.13 | G13: =SUM(G4:G12) -> 2299.6 | H13: =SUM(H4:H12) -> 2715.37 | I13: =SUM(I4:I12) -> 2235.01 | ... AO13: =SUM(AO4:AO12) -> 1060.16 | AQ13: =SUM(AQ4:AQ12) -> 2616.1192
A14: Day care Farofa | B14: 369 | C14: 369 | D14: 369 | F14: 339.17 | G14: 339.17 | H14: 339.17 | I14: 339.17 | J14: 339.17 | K14: 339.17 | L14: 339.17 | M14: 339.17 | N14: 339.17 | O14: 339.17 | P14: 339.17 | Q14: 339.17 | R14: 366.17 | S14: 366.17 | T14: 366.17 | V14: 447 | W14: 670.5 | X14: 596 | Y14: 447 | Z14: 596 | AA14: =749.5-AA17 -> 670.5 | AB14: =675-AB17 -> 596 | AC14: =1171-AC17 -> 1092 | AD14: =643.38-AD17 -> 557.38 | AE14: =723-AE17 -> 637 | AF14: =484.12-AF17 -> 398.12 | AG14: 716.62 | AH14: 723 | AI14: 875.89 | AJ14: 563.78 | AK14: 0 | AL14: 0 | AQ14: =AVERAGE(Z14:AE14) -> 691.48
A15: Ração | B15: 274.9 | C15: 247.41 | D15: 229 | E15: 269.88 | F15: 274.31 | G15: 210.52 | I15: 251.91 | J15: 245.1 | K15: 245.21 | L15: =22.95+181.66 -> 204.61 | M15: 245 | N15: 272.56 | O15: 272.56 | P15: 227.22 | Q15: 286.91 | R15: 385.57 | S15: 243.9 | T15: 231.7 | U15: 243.86 | W15: =243.86+44.08 -> 287.94 | X15: 221.98 | Z15: 287.5 | AA15: 299.16 | AB15: 299.16 | AC15: 299.16 | AD15: 330.12 | AE15: 342.85 | AF15: 342.85 | AQ15: =AVERAGE(AD15:AF15) -> 338.60667
A16: Plano de saúde | L16: 49.9 | M16: 49.9 | N16: 49.9 | O16: 49.9 | P16: 49.9 | Q16: 49.9 | R16: 49.9 | S16: 49.9 | T16: 49.9 | U16: 49.9 | V16: 49.9 | W16: 49.9 | X16: 49.9 | Y16: 52.49 | Z16: 52.49 | AA16: 52.49 | AB16: 52.49 | AC16: 52.49 | AD16: 52.49 | AE16: 52.49 | AF16: 52.49 | AQ16: =AF16 -> 52.49
A17: Banho | B17: 89 | D17: 90 | G17: 75 | I17: 90 | K17: 99.9 | O17: 55 | P17: 55 | R17: 55 | S17: 75 | T17: 57 | W17: 67 | Y17: 79 | Z17: 79 | AA17: 79 | AB17: 79 | AC17: 79 | AD17: 86 | AE17: 86 | AF17: 86 | AG17: 0 | AH17: 0 | AI17: 0 | AJ17: 0 | AK17: 86 | AL17: 0 | AQ17: =AF17 -> 86
A18: Antipulga | B18: 262.79 | C18: 662 | F18: 393.95 | I18: 312.75 | M18: 297.11 | O18: 72.68 | P18: 235.9 | Q18: 32.85 | S18: =50.41+247.9 -> 298.31 | W18: 249.9
A19: Demais gastos Farofa | B19: 0 | D19: =200+258.71 -> 458.71 | F19: =70+75 -> 145 | H19: =425+148.34+31.29+220 -> 824.63 | I19: 130 | K19: =240.5+180+210.4+66.69+264.17 -> 961.76 | N19: =72.68+32.85+123.94 -> 229.47 | O19: =45.8 -> 45.8 | U19: =40 -> 40 | V19: =107.54+25 -> 132.54 | W19: 91 | X19: 26.3 | Z19: 232.37 | AF19: 220
A20: Total Farofa | B20: =SUM(B14:B19) -> 995.69 | C20: =SUM(C14:C19) -> 1278.41 | D20: =SUM(D14:D19) -> 1146.71 | E20: =SUM(E14:E19) -> 269.88 | F20: =SUM(F14:F19) -> 1152.43 | G20: =SUM(G14:G19) -> 624.69 | H20: =SUM(H14:H19) -> 1163.8 | I20: =SUM(I14:I19) -> 1123.83 | ... AO20: =SUM(AO14:AO19) -> 0 | AQ20: =SUM(AQ14:AQ19) -> 1168.5767
A21: IPVA | Z21: =3080.27 -> 3080.27 | AL21: 2789.68 | AQ21: =Z21/12 -> 256.68917
A22: Seguro | Y22: 2682.75 | AJ22: 2433.02 | AQ22: =Y22/12 -> 223.5625
A23: Sem Parar | Y23: 160.35 | Z23: 266 | AA23: 180.2 | AB23: 149.89 | AC23: 294.98 | AD23: 223.1 | AE23: 270.92 | AQ23: =AVERAGE(Z23:AE23) -> 230.84833
A24: Combustível | Y24: =155.81+152.14+170 -> 477.95 | Z24: =155.81+152.14+170 -> 477.95 | AA24: =155.81+152.14+170 -> 477.95 | AB24: =155.81+152.14+170 -> 477.95 | AC24: =150.52+154.36+123.02 -> 427.9 | AD24: =155.81+152.14+170 -> 477.95 | AE24: =175.93+148.74+157.88 -> 482.55 | AQ24: =AVERAGE(Z24:AE24) -> 470.375 | AT24: Café da manhã
A25: Manutenção Carro | Z25: 3572.93 | AB25: =533.5 -> 533.5 | AL25: =6676.31 -> 6676.31 | AQ25: =SUM(Z25:AB25)/6 -> 684.405 | AT25: Sábados de la do pão | AU25: =60*4 -> 240
A26: Total Carro | B26: =SUM(B21:B25) -> 0 | C26: =SUM(C21:C25) -> 0 | D26: =SUM(D21:D25) -> 0 | E26: =SUM(E21:E25) -> 0 | F26: =SUM(F21:F25) -> 0 | G26: =SUM(G21:G25) -> 0 | H26: =SUM(H21:H25) -> 0 | I26: =SUM(I21:I25) -> 0 | ... AO26: =SUM(AO21:AO25) -> 0 | AQ26: =SUM(AQ21:AQ25) -> 1865.88 | AT26: +1 mês | AU26: 150
A27: Mercado | Z27: =420+96.73+168.89+24.34 -> 709.96 | AA27: =420+213.26+335.91 -> 969.17 | AB27: =420+138.69+268.92+36.18+31.17 -> 894.96 | AC27: =420+492.95 -> 912.95 | AD27: =193.3+420+144.05+378.1 -> 1135.45 | AE27: =237.63+223.26+293.37+420 -> 1174.26 | AQ27: =SUM(AA27:AE27)/5 -> 1017.358 | AT27: Almoço
A28: Alimentação | Z28: =117.5 -> 117.5 | AB28: =74.3+176+50+57.6+77.52+78.5+59.7+129.99+38.5+54.9+176+11.6+62+36+113+139.9 -> 1335.51 | AC28: =206.8+116.79 -> 323.59 | AD28: =195+139.9+64.59+63.3+161.59+75.6+214.62+75.4+128.79+62+113.3+152.88+249.67+10.5+277.78+68.4+52.56 -> 2105.88 | AE28: =250.86+22.1+84+90.87+12.62+59.64+69.88+116.05+69.5+105+436.15+51.94+25+64+54.5+197.6+88.68+29+83+22.84+160+127.69+171.77+45.1+51.7+476.86+18.07+15.05 -> 2999.47 | AF28: =100.18+70.9+175.32+14.23+71.46+227.56 -> 659.65 | AQ28: =SUM(AD28:AE28,AB28)/3 -> 2146.9533 | AT28: 2 por mês | AU28: =200*2 -> 400
A29: Vinho | R29: =90+387+150 -> 627 | T29: =204.3-30 -> 174.3 | AE29: =127.26+100 -> 227.26 | AT29: Jantar
A30: Total alimentação | B30: =SUM(B27:B29) -> 0 | C30: =SUM(C27:C29) -> 0 | D30: =SUM(D27:D29) -> 0 | E30: =SUM(E27:E29) -> 0 | F30: =SUM(F27:F29) -> 0 | G30: =SUM(G27:G29) -> 0 | H30: =SUM(H27:H29) -> 0 | I30: =SUM(I27:I29) -> 0 | ... AO30: =SUM(AO27:AO29) -> 0 | AQ30: =SUM(AQ27:AQ29) -> 3164.3113 | AT30: +1,5 por semana | AU30: =120*1.5*4 -> 720
A31: Empréstimo Casa | T31: 7916.6667 | U31: 7916.6667 | V31: 7916.6667 | W31: 7916.6667 | X31: 7916.6667 | Y31: 7916.6667 | Z31: 7916.6667 | AA31: 7916.6667 | AB31: 7916.6667 | AC31: 7916.6667 | AD31: 7916.6667 | AE31: 7916.6667 | AF31: 7916.6667 | AG31: 7916.6667 | AH31: 7916.6667 | AI31: 7916.6667 | AJ31: 7916.6667 | AK31: 7916.6667 | AL31: 7916.6667 | AM31: 7916.6667 | AN31: 7916.6667 | AO31: 7916.6667 | AQ31: =SUM(Z31:AK31)/12 -> 7916.6667
A32: Crédito Master | AF32: 1069.38 | AG32: 7636.98 | AH32: 17457.05 | AI32: 7249.5 | AJ32: 2017.97 | AK32: 1501.02 | AL32: 1718.55
A33: Crédito Visa | AI33: 11112.44 | AJ33: =12466.5-AJ22 -> 10033.48 | AK33: 8981.89 | AL33: =13454.02-AL25+2000 -> 8777.71
A34: Total Cartão | Z34: =SUM(Z32:Z33) -> 0 | AA34: =SUM(AA32:AA33) -> 0 | AB34: =SUM(AB32:AB33) -> 0 | AC34: =SUM(AC32:AC33) -> 0 | AD34: =SUM(AD32:AD33) -> 0 | AE34: =SUM(AE32:AE33) -> 0 | AF34: =SUM(AF32:AF33) -> 1069.38 | AG34: =SUM(AG32:AG33) -> 7636.98 | ... AO34: =SUM(AO32:AO33) -> 0
A35: Total mês (com empréstimo) | B35: =B20+B13+B26+B30 -> 2687.8 | C35: =C20+C13+C26+C30 -> 3171.31 | D35: =D20+D13+D26+D30 -> 3192.92 | E35: =E20+E13+E26+E30 -> 2488.44 | F35: =F20+F13+F26+F30 -> 4109.56 | G35: =G20+G13+G26+G30 -> 2924.29 | H35: =H20+H13+H26+H30 -> 3879.17 | I35: =I20+I13+I26+I30 -> 3358.84 | ... Y35: =Y20+Y13+Y26+Y30 -> 6429.34 | Z35: =Z$20+Z$13+Z$26+Z$30+Z$34 -> 15369.03 | AA35: =AA$20+AA$13+AA$26+AA$30+AA$34 -> 5196.59 | AB35: =AB$20+AB$13+AB$26+AB$30+AB$34 -> 7017.24 | AC35: =AC$20+AC$13+AC$26+AC$30+AC$34 -> 5817.75 | AD35: =AD$20+AD$13+AD$26+AD$30+AD$34 -> 7370.13 | AE35: =AE$20+AE$13+AE$26+AE$30+AE$34 -> 8386.28 | AF35: =AF$20+AF$13+AF$26+AF$30+AF$34 -> 4951.52 | AG35: =AG$20+AG$13+AG$26+AG$30+AG$34 -> 11179.35 | ... AO35: =AO$20+AO$13+AO$26+AO$30+AO$34 -> 1060.16 | AQ35: =AQ20+AQ13+AQ26+AQ30 -> 8814.8872 | AT35: +1 especial/mês | AU35: 350
A37: Total por xuxu (com empréstimo) | B37: =B35/2 -> 1343.9 | C37: =C35/2 -> 1585.655 | D37: =D35/2 -> 1596.46 | E37: =E35/2 -> 1244.22 | F37: =F35/2 -> 2054.78 | G37: =G35/2 -> 1462.145 | H37: =H35/2 -> 1939.585 | I37: =I35/2 -> 1679.42 | ... AO37: =AO35/2 -> 530.08 | AQ37: =AQ35/2 -> 4407.4436
A39: Total mês (sem empréstimo) | B39: =B24+B17+B30+B35 -> 2776.8 | C39: =C24+C17+C30+C35 -> 3171.31 | D39: =D24+D17+D30+D35 -> 3282.92 | E39: =E24+E17+E30+E35 -> 2488.44 | F39: =F24+F17+F30+F35 -> 4109.56 | G39: =G24+G17+G30+G35 -> 2999.29 | H39: =H24+H17+H30+H35 -> 3879.17 | I39: =I24+I17+I30+I35 -> 3448.84 | ... Y39: =Y24+Y17+Y30+Y35 -> 6986.29 | Z39: =Z$20+Z$13+Z$26+Z$30+Z$34-Z31 -> 7452.3633 | AA39: =AA$20+AA$13+AA$26+AA$30+AA$34-AA31 -> -2720.0767 | AB39: =AB$20+AB$13+AB$26+AB$30+AB$34-AB31 -> -899.42667 | AC39: =AC$20+AC$13+AC$26+AC$30+AC$34-AC31 -> -2098.9167 | AD39: =AD$20+AD$13+AD$26+AD$30+AD$34-AD31 -> -546.53667 | AE39: =AE$20+AE$13+AE$26+AE$30+AE$34-AE31 -> 469.61333 | AF39: =AF$20+AF$13+AF$26+AF$30+AF$34-AF31 -> -2965.1467 | AG39: =AG$20+AG$13+AG$26+AG$30+AG$34-AG31 -> 3262.6833 | ... AO39: =AO$20+AO$13+AO$26+AO$30+AO$34-AO31 -> -6856.5067 | AQ39: =AQ24+AQ17+AQ30+AQ35 -> 12535.574 | AT39: +1 especial/mês | AU39: 350
A41: Total por xuxu (sem empréstimo) | B41: =B39/2 -> 1388.4 | C41: =C39/2 -> 1585.655 | D41: =D39/2 -> 1641.46 | E41: =E39/2 -> 1244.22 | F41: =F39/2 -> 2054.78 | G41: =G39/2 -> 1499.645 | H41: =H39/2 -> 1939.585 | I41: =I39/2 -> 1724.42 | ... AO41: =AO39/2 -> -3428.2533 | AQ41: =AQ39/2 -> 6267.7868

Sheet Gastos Obra 2025
A1: Gastos obra 2025
F3: Saldo casamento | G3: =50000-B4-B5-B8 -> 4566.3
A4: Cobertura | B4: =7875+15500+7875 -> 31250
A5: Bambu | B5: 6883.7
A6: Material: iluminação | B6: =966.71+171.9-2.54 -> 1136.07 | C6: Cartão de crédito
A7: Material: cimento queimado | B7: 629.9 | C7: Cartão de crédito
A8: Vando (Total 7,8k) | B8: =3900+2000+1400 -> 7300
A9: Gastos Vando | B9: =54+55+66.3+157.3+35+43+37+104+32 -> 583.6
C10: Incluir custos marmoraria e compra adicional massa corrida
